Workbook

Sheet base
A1: rbd | B1: NOM RBD | C1: NOM_COM_RBD | D1: NOM_REG_RBD_A | E1: COD_DEPE2 | F1: Simce Lect 2022 4B | G1: Simce Lect 2023 4B | H1: Simce Lect 2024 4B | I1: Simce Lect 2025 4B | J1: Simce Mate 2022 4B | K1: Simce Mate 2023 4B | L1: Simce Mate 2024 4B | M1: Simce Mate 2025 4B | N1: Simce Lect 2022 2M | O1: Simce Lect 2023 2M | P1: Simce Lect 2024 2M | Q1: Simce Lect 2025 2M | R1: Simce Mate 2022 2M | S1: Simce Mate 2023 2M | T1: Simce Mate 2024 2M | U1: Simce Mate 2025 2M | V1: P_2022 2M | W1: P_2023 2M | X1: P_2024 2M | Y1: P_2025 2M | Z1: U_2022 2M | AA1: U_2023 2M | AB1: U_2024 2M | AC1: U_2025 2M | AD1: D_2022 2M | AE1: D_2023 2M | AF1: D_2024 2M | AG1: D_2025 2M | AH1: 1 Autoestima Académica y Motivación Escolar 4B | AI1: 2 Clima de Convivencia Escolar 4B | AJ1: 3 Participación y Formación Ciudadana 4B | AK1: 4 Hábitos de Vida Saludable 4B | AL1: 1 Autoestima Académica y Motivación Escolar 2M | AM1: 2 Clima de Convivencia Escolar 2M | AN1: 3 Participación y Formación Ciudadana 2M | AO1: 4 Hábitos de Vida Saludable 2M
A2: 1 | B2: LICEO POLITECNICO ARICA | C2: ARICA | D2: AYP | E2: 5: Servicio Local de Educación | N2: 218 | O2: 208 | P2: 227 | Q2: 207 | R2: 242 | S2: 214 | T2: 270 | U2: 243 | V2: 516.32432 | W2: 478.95968 | X2: 519.47458 | Y2: 502.91538 | Z2: 0.1119403 | AA2: 0.13043478 | AB2: 0.12352941 | AC2: 0.12637363 | AD2: 0 | AE2: 6 | AF2: 1 | AG2: 1 | AL2: 70 | AM2: 70.333333 | AN2: 73 | AO2: 71.333333
A3: 4 | B3: LICEO OCTAVIO PALMA PEREZ | C3: ARICA | D3: AYP | E3: 5: Servicio Local de Educación | N3: 268 | O3: 275 | P3: 280 | Q3: 283 | R3: 283 | S3: 284 | T3: 288 | U3: 297 | V3: 606.17904 | W3: 610.80182 | X3: 627.94872 | Y3: 620.16216 | Z3: 0.55462185 | AA3: 0.62962963 | AB3: 0.6227758 | AC3: 0.59330144 | AD3: 4 | AE3: 5 | AF3: 5 | AG3: 2 | AL3: 74 | AM3: 74.666667 | AN3: 75.666667 | AO3: 68.333333
A4: 5 | B4: JOVINA NARANJO FERNANDEZ | C4: ARICA | D4: AYP | E4: 5: Servicio Local de Educación | F4: 265 | G4: 264 | H4: 284 | I4: 279 | J4: 230 | K4: 243 | L4: 261 | M4: 266 | N4: 236 | O4: 242 | P4: 250 | Q4: 250 | R4: 251 | S4: 290 | T4: 244 | U4: 276 | V4: 566.648 | W4: 560.74074 | X4: 567.14019 | Y4: 583.65164 | Z4: 0.4 | AA4: 0.17274939 | AB4: 0.21501706 | AC4: 0.37278107 | AD4: 1 | AE4: 4 | AF4: 5 | AG4: 7 | AH4: 76.5 | AI4: 79 | AJ4: 83 | AK4: 75.333333 | AL4: 72 | AM4: 73.333333 | AN4: 77.333333 | AO4: 71.666667
A5: 7 | B5: L. POLI. BICENTENARIO DE EXCELENCIA ANTONIO VARAS DE LA BARRA | C5: ARICA | D5: AYP | E5: 5: Servicio Local de Educación | N5: 223 | O5: 228 | P5: 231 | Q5: 233 | R5: 225 | S5: 221 | T5: 239 | U5: 241 | V5: 508.9012 | W5: 505.75549 | X5: 515.73311 | Y5: 532.34731 | Z5: 0.14056225 | AA5: 0.22307692 | AB5: 0.13028169 | AC5: 0.27848101 | AD5: 6 | AE5: 3 | AF5: 6 | AG5: 7 | AL5: 72 | AM5: 76.333333 | AN5: 76 | AO5: 72
A6: 8 | B6: COLEGIO EDUARDO FREI MONTALVA | C6: ARICA | D6: AYP | E6: 5: Servicio Local de Educación | F6: 267 | G6: 291 | H6: 299 | I6: 284 | J6: 244 | K6: 279 | L6: 292 | M6: 277 | N6: 228 | O6: 238 | P6: 236 | Q6: 247 | R6: 236 | S6: 250 | T6: 252 | U6: 268 | V6: 537.89286 | W6: 543.36765 | X6: 572.7766 | Y6: 571.05882 | Z6: 0.27419355 | AA6: 0.32258065 | AB6: 0.25531915 | AC6: 0.35483871 | AD6: 2 | AE6: 6 | AF6: 6 | AG6: 3 | AH6: 84.5 | AI6: 84 | AJ6: 87.666667 | AK6: 76.666667 | AL6: 75.5 | AM6: 77 | AN6: 78.333333 | AO6: 72.666667
A7: 9 | B7: ESCUELA REPUBLICA DE ISRAEL | C7: ARICA | D7: AYP | E7: 5: Servicio Local de Educación | F7: 273 | G7: 284 | H7: 278 | I7: 277 | J7: 256 | K7: 265 | L7: 272 | M7: 259 | AD7: 5 | AE7: 7 | AF7: 5 | AG7: 7 | AH7: 72 | AI7: 74.333333 | AJ7: 75 | AK7: 68
A8: 10 | B8: ESCUELA REPUBLICA DE FRANCIA | C8: ARICA | D8: AYP | E8: 5: Servicio Local de Educación | F8: 273 | G8: 276 | H8: 262 | I8: 282 | J8: 216 | K8: 270 | L8: 240 | M8: 249 | AD8: 0 | AE8: 1 | AF8: 1 | AG8: 6 | AH8: 77 | AI8: 74.333333 | AJ8: 78.333333 | AK8: 69.666667
A9: 11 | B9: ESC. GRAL. PEDRO LAGOS MARCHANT | C9: ARICA | D9: AYP | E9: 5: Servicio Local de Educación | F9: 283 | G9: 257 | H9: 249 | I9: 255 | J9: 263 | K9: 243 | L9: 238 | M9: 216 | AD9: 1 | AE9: 4 | AF9: 4 | AG9: 2 | AH9: 79 | AI9: 76.666667 | AJ9: 80 | AK9: 70
A10: 12 | B10: ESCUELA GRAL JOSE MIGUEL CARRERA | C10: ARICA | D10: AYP | E10: 5: Servicio Local de Educación | F10: 259 | G10: 261 | H10: 285 | I10: 284 | J10: 232 | K10: 261 | L10: 260 | M10: 262 | AD10: 2 | AE10: 1 | AF10: 1 | AG10: 4 | AH10: 87 | AI10: 86 | AJ10: 92.333333 | AK10: 76.666667
A11: 13 | B11: ESCUELA MANUEL RODRIGUEZ ERDOYZA | C11: ARICA | D11: AYP | E11: 5: Servicio Local de Educación | F11: 235 | G11: 263 | H11: 274 | I11: 249 | J11: 220 | K11: 239 | L11: 257 | M11: 229 | AD11: 3 | AE11: 2 | AF11: 4 | AG11: 7 | AH11: 81.5 | AI11: 81 | AJ11: 85 | AK11: 72.333333
A12: 14 | B12: ESCUELA ROMULO J. PENA MATURANA | C12: ARICA | D12: AYP | E12: 5: Servicio Local de Educación | F12: 262 | G12: 256 | H12: 274 | I12: 277 | J12: 230 | K12: 253 | L12: 254 | M12: 257 | AD12: 0 | AE12: 0 | AF12: 0 | AG12: 1 | AH12: 77 | AI12: 0 | AJ12: 81 | AK12: 70.666667
A13: 15 | B13: LICEO BICENTENARIO ARTISTICO DR. JUAN NOE CREVANI | C13: ARICA | D13: AYP | E13: 5: Servicio Local de Educación | F13: 267 | G13: 258 | H13: 272 | I13: 265 | J13: 234 | K13: 254 | L13: 244 | M13: 243 | N13: 261 | O13: 261 | P13: 259 | Q13: 246 | R13: 244 | S13: 243 | T13: 251 | U13: 240 | V13: 566.90625 | W13: 551.78571 | X13: 562.90476 | Y13: 592.77273 | Z13: 0.17241379 | AA13: 0.2173913 | AB13: 0.36 | AC13: 0.51851852 | AD13: 4 | AE13: 3 | AF13: 1 | AG13: 7 | AH13: 76 | AI13: 71 | AJ13: 81 | AK13: 73 | AL13: 71 | AM13: 68.666667 | AN13: 70.666667 | AO13: 58
A14: 16 | B14: ESCUELA REGIMIENTO RANCAGUA | C14: ARICA | D14: AYP | E14: 5: Servicio Local de Educación | F14: 237 | G14: 242 | H14: 232 | I14: 247 | J14: 222 | K14: 226 | L14: 227 | M14: 249 | AD14: 2 | AE14: 1 | AF14: 1 | AG14: 0 | AH14: 76 | AI14: 80.333333 | AJ14: 83 | AK14: 72
A15: 17 | B15: ESCUELA SUBTTE. LUIS CRUZ MARTINEZ | C15: ARICA | D15: AYP | E15: 5: Servicio Local de Educación | F15: 226 | G15: 274 | H15: 268 | I15: 307 | J15: 219 | K15: 259 | L15: 265 | M15: 287 | AD15: 0 | AE15: 3 | AF15: 3 | AG15: 3 | AH15: 85.5 | AI15: 84.333333 | AJ15: 91.666667 | AK15: 78.666667
A16: 18 | B16: ESC. COMTE. JUAN JOSE SAN MARTIN | C16: ARICA | D16: AYP | E16: 5: Servicio Local de Educación | F16: 230 | G16: 279 | H16: 271 | I16: 267 | J16: 210 | K16: 263 | L16: 267 | M16: 244 | AD16: 0 | AE16: 0 | AF16: 1 | AG16: 3 | AH16: 84.5 | AI16: 84 | AJ16: 90.666667 | AK16: 77.333333
A17: 19 | B17: ESC. HUMBERTO VALENZUELA GARCIA | C17: ARICA | D17: AYP | E17: 5: Servicio Local de Educación | F17: 290 | G17: 268 | H17: 261 | I17: 242 | J17: 248 | K17: 246 | L17: 252 | M17: 248 | AD17: 0 | AE17: 3 | AF17: 0 | AG17: 2 | AH17: 76.5 | AI17: 74.666667 | AJ17: 80.666667 | AK17: 74.666667
A18: 20 | B18: ESCUELA TUCAPEL | C18: ARICA | D18: AYP | E18: 5: Servicio Local de Educación | F18: 252 | G18: 250 | H18: 276 | I18: 241 | J18: 235 | K18: 245 | L18: 265 | M18: 240 | AD18: 4 | AE18: 1 | AF18: 0 | AG18: 1 | AH18: 76.5 | AI18: 75 | AJ18: 77.333333 | AK18: 71.666667
A19: 22 | B19: ESCUELA GABRIELA MISTRAL | C19: ARICA | D19: AYP | E19: 5: Servicio Local de Educación | F19: 263 | G19: 267 | H19: 278 | I19: 258 | J19: 243 | K19: 263 | L19: 260 | M19: 259 | AD19: 5 | AE19: 5 | AF19: 1 | AG19: 2 | AH19: 73 | AI19: 74.666667 | AJ19: 77 | AK19: 71.333333
A20: 25 | B20: COLEGIO CENTENARIO DE ARICA | C20: ARICA | D20: AYP | E20: 5: Servicio Local de Educación | F20: 268 | G20: 253 | H20: 246 | I20: 258 | J20: 252 | K20: 243 | L20: 235 | M20: 255 | N20: 245 | O20: 222 | P20: 253 | Q20: 251 | R20: 241 | S20: 226 | T20: 222 | U20: 233 | V20: 543 | W20: 531.23077 | X20: 551.1375 | Y20: 542.36047 | Z20: 0.21428571 | AA20: 0.34615385 | AB20: 0.2826087 | AC20: 0.45283019 | AD20: 3 | AE20: 0 | AF20: 0 | AG20: 3 | AH20: 74 | AI20: 71 | AJ20: 76.666667 | AK20: 69.666667 | AL20: 76.5 | AM20: 76.666667 | AN20: 78.666667 | AO20: 73.333333
A21: 26 | B21: ESCUELA REPUBLICA DE ARGENTINA | C21: ARICA | D21: AYP | E21: 5: Servicio Local de Educación | F21: 247 | G21: 257 | H21: 264 | I21: 261 | J21: 230 | K21: 259 | L21: 264 | M21: 250 | AD21: 0 | AE21: 2 | AF21: 5 | AG21: 1 | AH21: 73.5 | AI21: 77.666667 | AJ21: 81.666667 | AK21: 72
A22: 27 | B22: ESCUELA ESMERALDA | C22: ARICA | D22: AYP | E22: 5: Servicio Local de Educación | F22: 274 | G22: 298 | H22: 298 | I22: 251 | J22: 277 | K22: 281 | L22: 305 | M22: 255 | AD22: 1 | AE22: 0 | AF22: 5 | AG22: 4 | AH22: 76.5 | AI22: 76 | AJ22: 83.333333 | AK22: 72.333333
A23: 28 | B23: ESCUELA RICARDO SILVA ARRIAGADA | C23: ARICA | D23: AYP | E23: 5: Servicio Local de Educación | F23: 272 | G23: 285 | H23: 293 | I23: 291 | J23: 256 | K23: 269 | L23: 301 | M23: 287 | V23: 534.33333 | W23: 410.5 | X23: 447.5 | Y23: 533.78571 | Z23: 0.012048193 | AA23: 0.042857143 | AB23: 0.022727273 | AC23: 0.014705882 | AD23: 2 | AE23: 1 | AF23: 0 | AG23: 4 | AH23: 79 | AI23: 79.666667 | AJ23: 81.333333 | AK23: 71.666667
A24: 29 | B24: ESCUELA AMERICA | C24: ARICA | D24: AYP | E24: 5: Servicio Local de Educación | F24: 278 | G24: 214 | H24: 251 | I24: 264 | J24: 253 | K24: 209 | L24: 240 | M24: 227 | AD24: 3 | AE24: 3 | AF24: 2 | AG24: 1 | AH24: 81 | AI24: 80 | AJ24: 79.333333 | AK24: 72
A25: 31 | B25: ESCUELA DARIO SALAS DIAZ | C25: ARICA | D25: AYP | E25: 5: Servicio Local de Educación | F25: 242 | G25: 237 | H25: 255 | I25: 250 | J25: 257 | K25: 250 | L25: 268 | M25: 253 | AD25: 4 | AE25: 1 | AF25: 0 | AG25: 1 | AH25: 72.5 | AI25: 72.333333 | AJ25: 75.333333 | AK25: 66
A26: 32 | B26: LICEO AGRICOLA JOSE ABELARDO NUNEZ M. | C26: ARICA | D26: AYP | E26: 5: Servicio Local de Educación | F26: 251 | G26: 300 | H26: 289 | I26: 293 | J26: 232 | K26: 290 | L26: 289 | M26: 291 | N26: 204 | O26: 231 | P26: 226 | Q26: 239 | R26: 209 | S26: 233 | T26: 265 | U26: 245 | V26: 510.90625 | W26: 494.07143 | X26: 480.14286 | Y26: 514.2907 | Z26: 0.30434783 | AA26: 0.46666667 | AB26: 0.28571429 | AC26: 0.35294118 | AD26: 0 | AE26: 1 | AF26: 1 | AG26: 1 | AH26: 81 | AI26: 80.333333 | AJ26: 82.666667 | AK26: 74 | AL26: 81.5 | AM26: 82.666667 | AN26: 85.666667 | AO26: 80.666667
A27: 33 | B27: ESCUELA CARLOS CONDELL DE LA HAZA | C27: ARICA | D27: AYP | E27: 5: Servicio Local de Educación | F27: 294 | G27: 259 | H27: 330 | I27: 304 | J27: 295 | K27: 271 | L27: 306 | M27: 302 | AG27: 0 | AH27: 84.5 | AI27: 80 | AJ27: 85.333333 | AK27: 74.333333
A28: 35 | B28: ESCUELA GRAL. MANUEL BAQUEDANO | C28: ARICA | D28: AYP | E28: 5: Servicio Local de Educación | F28: 237 | G28: 231 | H28: 243 | I28: 262 | J28: 237 | K28: 221 | L28: 238 | M28: 260 | AD28: 0 | AE28: 0 | AF28: 0 | AG28: 3 | AH28: 73 | AI28: 78.666667 | AJ28: 80 | AK28: 72.666667
A29: 36 | B29: ESCUELA IGNACIO CARRERA PINTO | C29: ARICA | D29: AYP | E29: 5: Servicio Local de Educación | F29: 240 | G29: 222 | H29: 222 | I29: 254 | J29: 232 | K29: 203 | L29: 233 | M29: 260 | AD29: 0 | AE29: 1 | AF29: 2 | AG29: 1 | AH29: 89.5 | AI29: 85.333333 | AJ29: 93.333333 | AK29: 76
A30: 38 | B30: ESCUELA ESPAÑA | C30: ARICA | D30: AYP | E30: 5: Servicio Local de Educación | F30: 251 | G30: 253 | H30: 273 | I30: 263 | J30: 245 | K30: 255 | L30: 286 | M30: 256 | AD30: 0 | AE30: 1 | AF30: 1 | AG30: 1 | AH30: 88 | AI30: 88.666667 | AJ30: 95 | AK30: 79
A31: 39 | B31: ESCUELA PAMPA ALGODONAL | C31: ARICA | D31: AYP | E31: 5: Servicio Local de Educación | F31: 219 | G31: 235 | H31: 267 | I31: 245 | J31: 216 | K31: 224 | L31: 241 | M31: 249 | AG31: 0 | AH31: 78 | AI31: 70.333333 | AJ31: 83.333333 | AK31: 71
A32: 41 | B32: ESCUELA VALLE DE CHACA | C32: ARICA | D32: AYP | E32: 5: Servicio Local de Educación | F32: 236 | G32: 231 | H32: 200 | I32: 244 | J32: 220 | K32: 218 | L32: 228 | M32: 235 | AG32: 0 | AH32: 77 | AI32: 76 | AJ32: 83.333333 | AK32: 66.333333
A33: 42 | B33: ESCUELA MOLINOS LLUTA | C33: ARICA | D33: AYP | E33: 5: Servicio Local de Educación | G33: 278 | H33: 249 | I33: 234 | K33: 238 | L33: 234 | M33: 240 | AG33: 0 | AH33: 78 | AI33: 74 | AJ33: 81 | AK33: 69.333333
A34: 45 | B34: COLEGIO ITALIANO SANTA ANA | C34: ARICA | D34: AYP | E34: 2: Particular Subvencionado | F34: 279 | G34: 321 | H34: 297 | I34: 279 | J34: 254 | K34: 292 | L34: 290 | M34: 264 | N34: 277 | O34: 271 | P34: 287 | Q34: 285 | R34: 312 | S34: 298 | T34: 344 | U34: 324 | V34: 573.40164 | W34: 581.45918 | X34: 594.25 | Y34: 612.84906 | Z34: 0.4109589 | AA34: 0.37878788 | AB34: 0.50909091 | AC34: 0.55384615 | AD34: 2 | AE34: 2 | AF34: 2 | AG34: 4 | AH34: 68 | AI34: 71.666667 | AJ34: 69.333333 | AK34: 65 | AL34: 79 | AM34: 82.333333 | AN34: 82.333333 | AO34: 76
A35: 50 | B35: COLEGIO ADVENTISTA DE ARICA | C35: ARICA | D35: AYP | E35: 2: Particular Subvencionado | F35: 293 | G35: 261 | H35: 273 | I35: 270 | J35: 252 | K35: 249 | L35: 266 | M35: 255 | N35: 274 | O35: 267 | P35: 262 | Q35: 267 | R35: 293 | S35: 285 | T35: 303 | U35: 315 | V35: 622.23256 | W35: 589.61842 | X35: 618.02564 | Y35: 637.53571 | Z35: 0.55555556 | AA35: 0.61363636 | AB35: 0.51282051 | AC35: 0.48837209 | AD35: 3 | AE35: 2 | AF35: 1 | AG35: 1 | AH35: 70.5 | AI35: 74.666667 | AJ35: 74 | AK35: 64.333333 | AL35: 73 | AM35: 79.666667 | AN35: 79.666667 | AO35: 77.333333
A36: 52 | B36: LICEO BICENTENARIO DOMINGO SANTA MARIA | C36: ARICA | D36: AYP | E36: 2: Particular Subvencionado | F36: 306 | G36: 301 | H36: 330 | I36: 290 | J36: 294 | K36: 289 | L36: 305 | M36: 282 | N36: 244 | O36: 257 | P36: 238 | Q36: 252 | R36: 252 | S36: 269 | T36: 270 | U36: 280 | V36: 554.75592 | W36: 550.30671 | X36: 578.20308 | Y36: 589.01282 | Z36: 0.35064935 | AA36: 0.35036496 | AB36: 0.34759358 | AC36: 0.39386189 | AD36: 10 | AE36: 7 | AF36: 1 | AG36: 6 | AH36: 71.5 | AI36: 75 | AJ36: 76 | AK36: 72.666667 | AL36: 73 | AM36: 76.333333 | AN36: 76.666667 | AO36: 74.666667
A37: 56 | B37: COLEGIO SAN MARCOS DE ARICA | C37: ARICA | D37: AYP | E37: 2: Particular Subvencionado | F37: 285 | G37: 309 | H37: 286 | I37: 298 | J37: 265 | K37: 273 | L37: 251 | M37: 266 | N37: 265 | O37: 282 | P37: 256 | Q37: 280 | R37: 294 | S37: 302 | T37: 274 | U37: 300 | V37: 660.49359 | W37: 643.52174 | X37: 665.38667 | Y37: 684.92763 | Z37: 0.56410256 | AA37: 0.70886076 | AB37: 0.5 | AC37: 0.48717949 | AD37: 1 | AE37: 6 | AF37: 3 | AG37: 11 | AH37: 73.5 | AI37: 76 | AJ37: 80 | AK37: 74 | AL37: 68 | AM37: 70.666667 | AN37: 74 | AO37: 68.666667
A38: 59 | B38: COLEGIO SAN JORGE | C38: ARICA | D38: AYP | E38: 3: Particular Pagado | F38: 297 | G38: 292 | H38: 281 | I38: 283 | J38: 292 | K38: 284 | L38: 292 | M38: 270 | N38: 243 | O38: 290 | P38: 274 | Q38: 259 | R38: 260 | S38: 275 | T38: 306 | U38: 281 | V38: 673.48958 | W38: 666.85294 | X38: 662.85 | Y38: 671.25 | Z38: 0.66666667 | AA38: 0.71428571 | AB38: 0.58823529 | AC38: 0.61290323 | AD38: 3 | AE38: 3 | AF38: 5 | AG38: 3 | AH38: 76 | AI38: 80 | AJ38: 82.666667 | AK38: 69.666667 | AL38: 74.5 | AM38: 80 | AN38: 81.333333 | AO38: 75
A39: 60 | B39: COLEGIO ALEMAN DE ARICA | C39: ARICA | D39: AYP | E39: 2: Particular Subvencionado | F39: 283 | G39: 275 | H39: 285 | I39: 278 | J39: 253 | K39: 270 | L39: 259 | M39: 253 | N39: 260 | O39: 278 | P39: 253 | Q39: 250 | R39: 271 | S39: 325 | T39: 314 | U39: 283 | V39: 592.72973 | W39: 617.04487 | X39: 626.54545 | Y39: 632.13253 | Z39: 0.5 | AA39: 0.48684211 | AB39: 0.5060241 | AC39: 0.37777778 | AD39: 6 | AE39: 5 | AF39: 2 | AG39: 2 | AH39: 66.5 | AI39: 68.666667 | AJ39: 68.333333 | AK39: 68.333333 | AL39: 70 | AM39: 74.333333 | AN39: 74.666667 | AO39: 68
A40: 67 | B40: ABRAHAM LINCOLN SCHOOL | C40: ARICA | D40: AYP | E40: 2: Particular Subvencionado | F40: 301 | G40: 284 | H40: 302 | I40: 265 | J40: 271 | K40: 265 | L40: 289 | M40: 238 | N40: 262 | O40: 256 | P40: 251 | Q40: 236 | R40: 268 | S40: 254 | T40: 250 | U40: 236 | V40: 621.63953 | W40: 612.72973 | X40: 633.68085 | Y40: 613.56667 | Z40: 0.64102564 | AA40: 0.69767442 | AB40: 0.76315789 | AC40: 0.70833333 | AD40: 10 | AE40: 6 | AF40: 6 | AG40: 7 | AH40: 63 | AI40: 69.666667 | AJ40: 66 | AK40: 66 | AL40: 65 | AM40: 68.666667 | AN40: 66.666667 | AO40: 57
...

Sheet resumen
C2: RBD | D2: 9013 | J2: RBD | K2: 14641
C3: Nombre RBD | D3: =VLOOKUP($D$2,base!$A$1:$AO$8407,2,0) -> ESCUELA PALESTINA | J3: Nombre RBD | K3: =VLOOKUP($K$2,base!$A$1:$AO$8407,2,0) -> COLEGIO PAULA VIVANCO
C4: Comuna | D4: =VLOOKUP($D$2,base!$A$1:$AO$8407,3,0) -> LA REINA | J4: Comuna | K4: =VLOOKUP($K$2,base!$A$1:$AO$8407,3,0) -> LIMACHE
C5: Dependencia | D5: =VLOOKUP($D$2,base!$A$1:$AO$8407,5,0) -> 1: Municipal | J5: Dependencia | K5: =VLOOKUP($K$2,base!$A$1:$AO$8407,5,0) -> 2: Particular Subvencionado
B7: Nivel | C7: Indicador | D7: 2022 | E7: 2023 | F7: 2024 | G7: 2025 | I7: Nivel | J7: Indicador | K7: 2022 | L7: 2023 | M7: 2024 | N7: 2025
B8: Total | C8: Denuncias | D8: =IFERROR(VLOOKUP($D$2,base!$A$1:$AO$8407,30,0),"") -> 3 | E8: =IFERROR(VLOOKUP($D$2,base!$A$1:$AO$8407,31,0),"") -> 3 | F8: =IFERROR(VLOOKUP($D$2,base!$A$1:$AO$8407,32,0),"") -> 5 | G8: =IFERROR(VLOOKUP($D$2,base!$A$1:$AO$8407,33,0),"") -> 2 | I8: Total | J8: Denuncias | K8: =IFERROR(VLOOKUP($K$2,base!$A$1:$AO$8407,30,0),"") -> 2 | L8: =IFERROR(VLOOKUP($K$2,base!$A$1:$AO$8407,31,0),"") -> 4 | M8: =IFERROR(VLOOKUP($K$2,base!$A$1:$AO$8407,32,0),"") -> 4 | N8: =IFERROR(VLOOKUP($K$2,base!$A$1:$AO$8407,33,0),"") -> 4
B9: 4to basico | C9: Simce lect | D9: =IFERROR(VLOOKUP($D$2,base!$A$1:$AO$8407,6,0),"") -> 289 | E9: =IFERROR(VLOOKUP($D$2,base!$A$1:$AO$8407,7,0),"") -> 280 | F9: =IFERROR(VLOOKUP($D$2,base!$A$1:$AO$8407,8,0),"") -> 299 | G9: =IFERROR(VLOOKUP($D$2,base!$A$1:$AO$8407,9,0),"") -> 315 | I9: 4to basico | J9: Simce lect | K9: =IFERROR(VLOOKUP($K$2,base!$A$1:$AO$8407,6,0),"") -> 277 | L9: =IFERROR(VLOOKUP($K$2,base!$A$1:$AO$8407,7,0),"") -> 299 | M9: =IFERROR(VLOOKUP($K$2,base!$A$1:$AO$8407,8,0),"") -> 276 | N9: =IFERROR(VLOOKUP($K$2,base!$A$1:$AO$8407,9,0),"") -> 256
C10: Simce mat | D10: =IFERROR(VLOOKUP($D$2,base!$A$1:$AO$8407,10,0),"") -> 268 | E10: =IFERROR(VLOOKUP($D$2,base!$A$1:$AO$8407,11,0),"") -> 285 | F10: =IFERROR(VLOOKUP($D$2,base!$A$1:$AO$8407,12,0),"") -> 289 | G10: =IFERROR(VLOOKUP($D$2,base!$A$1:$AO$8407,13,0),"") -> 300 | J10: Simce mat | K10: =IFERROR(VLOOKUP($K$2,base!$A$1:$AO$8407,10,0),"") -> 278 | L10: =IFERROR(VLOOKUP($K$2,base!$A$1:$AO$8407,11,0),"") -> 290 | M10: =IFERROR(VLOOKUP($K$2,base!$A$1:$AO$8407,12,0),"") -> 270 | N10: =IFERROR(VLOOKUP($K$2,base!$A$1:$AO$8407,13,0),"") -> 258
B11: 2do medio | C11: Simce lect | D11: =IFERROR(VLOOKUP($D$2,base!$A$1:$AO$8407,15,0),"") -> 0 | E11: =IFERROR(VLOOKUP($D$2,base!$A$1:$AO$8407,15,0),"") -> 0 | F11: =IFERROR(VLOOKUP($D$2,base!$A$1:$AO$8407,16,0),"") -> 0 | G11: =IFERROR(VLOOKUP($D$2,base!$A$1:$AO$8407,17,0),"") -> 0 | I11: 2do medio | J11: Simce lect | K11: =IFERROR(VLOOKUP($K$2,base!$A$1:$AO$8407,15,0),"") -> 251 | L11: =IFERROR(VLOOKUP($K$2,base!$A$1:$AO$8407,15,0),"") -> 251 | M11: =IFERROR(VLOOKUP($K$2,base!$A$1:$AO$8407,16,0),"") -> 259 | N11: =IFERROR(VLOOKUP($K$2,base!$A$1:$AO$8407,17,0),"") -> 249
C12: Simce 2 mat | D12: =IFERROR(VLOOKUP($D$2,base!$A$1:$AO$8407,18,0),"") -> 0 | E12: =IFERROR(VLOOKUP($D$2,base!$A$1:$AO$8407,19,0),"") -> 0 | F12: =IFERROR(VLOOKUP($D$2,base!$A$1:$AO$8407,20,0),"") -> 0 | G12: =IFERROR(VLOOKUP($D$2,base!$A$1:$AO$8407,21,0),"") -> 0 | J12: Simce 2 mat | K12: =IFERROR(VLOOKUP($K$2,base!$A$1:$AO$8407,18,0),"") -> 278 | L12: =IFERROR(VLOOKUP($K$2,base!$A$1:$AO$8407,19,0),"") -> 273 | M12: =IFERROR(VLOOKUP($K$2,base!$A$1:$AO$8407,20,0),"") -> 266 | N12: =IFERROR(VLOOKUP($K$2,base!$A$1:$AO$8407,21,0),"") -> 271
B13: 4to medio | C13: PAES | D13: =IFERROR(VLOOKUP($D$2,base!$A$1:$AO$8407,22,0),"") | E13: =IFERROR(VLOOKUP($D$2,base!$A$1:$AO$8407,23,0),"") | F13: =IFERROR(VLOOKUP($D$2,base!$A$1:$AO$8407,24,0),"") | G13: =IFERROR(VLOOKUP($D$2,base!$A$1:$AO$8407,25,0),"") -> 0 | I13: 4to medio | J13: PAES | K13: =IFERROR(VLOOKUP($K$2,base!$A$1:$AO$8407,22,0),"") -> 607.2037 | L13: =IFERROR(VLOOKUP($K$2,base!$A$1:$AO$8407,23,0),"") -> 607.51515 | M13: =IFERROR(VLOOKUP($K$2,base!$A$1:$AO$8407,24,0),"") -> 599.96552 | N13: =IFERROR(VLOOKUP($K$2,base!$A$1:$AO$8407,25,0),"") -> 631.58824
C14: Ingreso universidad | D14: =IFERROR(VLOOKUP($D$2,base!$A$1:$AO$8407,26,0),"") | E14: =IFERROR(VLOOKUP($D$2,base!$A$1:$AO$8407,27,0),"") | F14: =IFERROR(VLOOKUP($D$2,base!$A$1:$AO$8407,28,0),"") | G14: =IFERROR(VLOOKUP($D$2,base!$A$1:$AO$8407,29,0),"") -> 0 | J14: Ingreso universidad | K14: =IFERROR(VLOOKUP($K$2,base!$A$1:$AO$8407,26,0),"") -> 0.20689655 | L14: =IFERROR(VLOOKUP($K$2,base!$A$1:$AO$8407,27,0),"") -> 0.37037037 | M14: =IFERROR(VLOOKUP($K$2,base!$A$1:$AO$8407,28,0),"") -> 0.52941176 | N14: =IFERROR(VLOOKUP($K$2,base!$A$1:$AO$8407,29,0),"") -> 0.44117647
B15: 4to basico | C15: Autoestima Académica y Motivación Escolar | G15: =IFERROR(VLOOKUP($D$2,base!$A$1:$AO$8407,34,0),"") -> 79.5 | I15: 4to basico | J15: Autoestima Académica y Motivación Escolar | N15: =IFERROR(VLOOKUP($K$2,base!$A$1:$AO$8407,34,0),"") -> 64
C16: Clima de Convivencia Escolar | G16: =IFERROR(VLOOKUP($D$2,base!$A$1:$AO$8407,35,0),"") -> 79 | J16: Clima de Convivencia Escolar | N16: =IFERROR(VLOOKUP($K$2,base!$A$1:$AO$8407,35,0),"") -> 70.666667
C17: Participación y Formación Ciudadana | G17: =IFERROR(VLOOKUP($D$2,base!$A$1:$AO$8407,36,0),"") -> 81 | J17: Participación y Formación Ciudadana | N17: =IFERROR(VLOOKUP($K$2,base!$A$1:$AO$8407,36,0),"") -> 69.666667
C18: Hábitos de Vida Saludable | G18: =IFERROR(VLOOKUP($D$2,base!$A$1:$AO$8407,37,0),"") -> 73 | J18: Hábitos de Vida Saludable | N18: =IFERROR(VLOOKUP($K$2,base!$A$1:$AO$8407,37,0),"") -> 63.666667
B19: 2do medio | C19: Autoestima Académica y Motivación Escolar | G19: =IFERROR(VLOOKUP($D$2,base!$A$1:$AO$8407,38,0),"") -> 0 | I19: 2do medio | J19: Autoestima Académica y Motivación Escolar | N19: =IFERROR(VLOOKUP($K$2,base!$A$1:$AO$8407,38,0),"") -> 77
C20: Clima de Convivencia Escolar | G20: =IFERROR(VLOOKUP($D$2,base!$A$1:$AO$8407,39,0),"") -> 0 | J20: Clima de Convivencia Escolar | N20: =IFERROR(VLOOKUP($K$2,base!$A$1:$AO$8407,39,0),"") -> 76.666667
C21: Participación y Formación Ciudadana | G21: =IFERROR(VLOOKUP($D$2,base!$A$1:$AO$8407,40,0),"") -> 0 | J21: Participación y Formación Ciudadana | N21: =IFERROR(VLOOKUP($K$2,base!$A$1:$AO$8407,40,0),"") -> 78.666667
C22: Hábitos de Vida Saludable | G22: =IFERROR(VLOOKUP($D$2,base!$A$1:$AO$8407,41,0),"") -> 0 | J22: Hábitos de Vida Saludable | N22: =IFERROR(VLOOKUP($K$2,base!$A$1:$AO$8407,41,0),"") -> 68.666667

Sheet Hoja1
F1: rbd
F2: NOM RBD
F3: NOM_COM_RBD
F4: NOM_REG_RBD_A
F5: COD_DEPE2
F6: Simce Lect 2022 4B
F7: Simce Lect 2023 4B
F8: Simce Lect 2024 4B
F9: Simce Lect 2025 4B
F10: Simce Mate 2022 4B
F11: Simce Mate 2023 4B
F12: Simce Mate 2024 4B
... F41: 4 Hábitos de Vida Saludable 2M
